2021-12-03 09:36:51 DEBUG (SyncWorker_0) [homeassistant.util.yaml.loader] Secret myLatitude retrieved from secrets.yaml in folder /config
2021-12-03 09:36:51 DEBUG (SyncWorker_0) [homeassistant.util.yaml.loader] Secret myLongitude retrieved from secrets.yaml in folder /config
2021-12-03 09:36:52 DEBUG (SyncWorker_0) [homeassistant.util.yaml.loader] Secret myCamera retrieved from secrets.yaml in folder /config
2021-12-03 09:36:52 DEBUG (SyncWorker_0) [homeassistant.util.yaml.loader] Secret mariadb_connection_url retrieved from secrets.yaml in folder /config
2021-12-03 09:36:52 DEBUG (SyncWorker_0) [homeassistant.util.yaml.loader] Secret myLatitude retrieved from secrets.yaml in folder /config
2021-12-03 09:36:52 DEBUG (SyncWorker_0) [homeassistant.util.yaml.loader] Secret myLongitude retrieved from secrets.yaml in folder /config
2021-12-03 09:36:52 DEBUG (SyncWorker_0) [homeassistant.util.yaml.loader] Secret mqttBroker retrieved from secrets.yaml in folder /config
2021-12-03 09:36:52 DEBUG (SyncWorker_0) [homeassistant.util.yaml.loader] Secret mqttPort retrieved from secrets.yaml in folder /config
2021-12-03 09:36:52 DEBUG (SyncWorker_0) [homeassistant.util.yaml.loader] Secret mqttUser retrieved from secrets.yaml in folder /config
2021-12-03 09:36:52 DEBUG (SyncWorker_0) [homeassistant.util.yaml.loader] Secret mqttPassword retrieved from secrets.yaml in folder /config
2021-12-03 09:36:52 DEBUG (SyncWorker_0) [homeassistant.util.yaml.loader] Secret iftttApiKey retrieved from secrets.yaml in folder /config
2021-12-03 09:36:54 WARNING (MainThread) [homeassistant.components.updater] Analytics reporting with the option 'include_used_components' is deprecated and you should remove that from your configuration. The analytics part of this integration has moved to the new 'analytics' integration
2021-12-03 09:36:55 INFO (Thread-3) [homeassistant.components.mqtt] Connected to MQTT server mqtt:1883 (0)
2021-12-03 09:36:56 DEBUG (MainThread) [homeassistant.components.mqtt] Subscribing to homeassistant/+/+/config, mid: 1
2021-12-03 09:36:56 DEBUG (MainThread) [homeassistant.components.mqtt] Subscribing to homeassistant/+/+/+/config, mid: 2
2021-12-03 09:36:56 DEBUG (MainThread) [homeassistant.components.mqtt] Received message on homeassistant/sensor/bonsaitemp/living_room_temperature/config (retained): b'{"dev_cla":"temperature","unit_of_meas":"\xc2\xb0C","stat_cla":"measurement","name":"Living Room Temperature","stat_t":"bonsaitemp/sensor/living_room_temperature/state","avty_t":"bonsaitemp/status","uniq_id":"ESPsensorliving_room_temperature","dev":{"ids":"ecfabc212c26","name":"bonsaitemp","sw":"esphome v2021.11.4 Nov 30 2021, 13:49:26","mdl":"nodemcuv2","mf":"espressif"}}'
2021-12-03 09:36:56 DEBUG (MainThread) [homeassistant.components.mqtt] Received message on homeassistant/sensor/bonsaitemp/living_room_humidity/config (retained): b'{"dev_cla":"humidity","unit_of_meas":"%","stat_cla":"measurement","name":"Living Room Humidity","stat_t":"bonsaitemp/sensor/living_room_humidity/state","avty_t":"bonsaitemp/status","uniq_id":"ESPsensorliving_room_humidity","dev":{"ids":"ecfabc212c26","name":"bonsaitemp","sw":"esphome v2021.11.4 Nov 30 2021, 13:49:26","mdl":"nodemcuv2","mf":"espressif"}}'
2021-12-03 09:36:56 DEBUG (MainThread) [homeassistant.components.mqtt] Received message on homeassistant/sensor/bonsaitemp/outdoor_bonsai_temperature/config (retained): b'{"dev_cla":"temperature","unit_of_meas":"\xc2\xb0C","stat_cla":"measurement","name":"Outdoor Bonsai Temperature","stat_t":"bonsaitemp/sensor/outdoor_bonsai_temperature/state","avty_t":"bonsaitemp/status","uniq_id":"ESPsensoroutdoor_bonsai_temperature","dev":{"ids":"ecfabc212c26","name":"bonsaitemp","sw":"esphome v2021.11.4 Nov 30 2021, 13:59:55","mdl":"nodemcuv2","mf":"espressif"}}'
2021-12-03 09:36:56 DEBUG (MainThread) [homeassistant.components.mqtt] Received message on homeassistant/sensor/bonsaitemp/outdoor_bonsai_humidity/config (retained): b'{"dev_cla":"humidity","unit_of_meas":"%","stat_cla":"measurement","name":"Outdoor Bonsai Humidity","stat_t":"bonsaitemp/sensor/outdoor_bonsai_humidity/state","avty_t":"bonsaitemp/status","uniq_id":"ESPsensoroutdoor_bonsai_humidity","dev":{"ids":"ecfabc212c26","name":"bonsaitemp","sw":"esphome v2021.11.4 Nov 30 2021, 13:59:55","mdl":"nodemcuv2","mf":"espressif"}}'
2021-12-03 09:36:56 DEBUG (MainThread) [homeassistant.components.mqtt.discovery] Process discovery payload {'device_class': 'temperature', 'unit_of_measurement': '°C', 'state_class': 'measurement', 'name': 'Living Room Temperature', 'state_topic': 'bonsaitemp/sensor/living_room_temperature/state', 'availability_topic': 'bonsaitemp/status', 'unique_id': 'ESPsensorliving_room_temperature', 'device': {'identifiers': 'ecfabc212c26', 'name': 'bonsaitemp', 'sw_version': 'esphome v2021.11.4 Nov 30 2021, 13:49:26', 'model': 'nodemcuv2', 'manufacturer': 'espressif'}, 'platform': 'mqtt'}
2021-12-03 09:36:56 INFO (MainThread) [homeassistant.components.mqtt.discovery] Found new component: sensor bonsaitemp living_room_temperature
2021-12-03 09:36:56 DEBUG (MainThread) [homeassistant.components.mqtt.discovery] Process discovery payload {'device_class': 'humidity', 'unit_of_measurement': '%', 'state_class': 'measurement', 'name': 'Living Room Humidity', 'state_topic': 'bonsaitemp/sensor/living_room_humidity/state', 'availability_topic': 'bonsaitemp/status', 'unique_id': 'ESPsensorliving_room_humidity', 'device': {'identifiers': 'ecfabc212c26', 'name': 'bonsaitemp', 'sw_version': 'esphome v2021.11.4 Nov 30 2021, 13:49:26', 'model': 'nodemcuv2', 'manufacturer': 'espressif'}, 'platform': 'mqtt'}
2021-12-03 09:36:56 INFO (MainThread) [homeassistant.components.mqtt.discovery] Found new component: sensor bonsaitemp living_room_humidity
2021-12-03 09:36:56 DEBUG (MainThread) [homeassistant.components.mqtt.discovery] Process discovery payload {'device_class': 'temperature', 'unit_of_measurement': '°C', 'state_class': 'measurement', 'name': 'Outdoor Bonsai Temperature', 'state_topic': 'bonsaitemp/sensor/outdoor_bonsai_temperature/state', 'availability_topic': 'bonsaitemp/status', 'unique_id': 'ESPsensoroutdoor_bonsai_temperature', 'device': {'identifiers': 'ecfabc212c26', 'name': 'bonsaitemp', 'sw_version': 'esphome v2021.11.4 Nov 30 2021, 13:59:55', 'model': 'nodemcuv2', 'manufacturer': 'espressif'}, 'platform': 'mqtt'}
2021-12-03 09:36:56 INFO (MainThread) [homeassistant.components.mqtt.discovery] Found new component: sensor bonsaitemp outdoor_bonsai_temperature
2021-12-03 09:36:56 DEBUG (MainThread) [homeassistant.components.mqtt.discovery] Process discovery payload {'device_class': 'humidity', 'unit_of_measurement': '%', 'state_class': 'measurement', 'name': 'Outdoor Bonsai Humidity', 'state_topic': 'bonsaitemp/sensor/outdoor_bonsai_humidity/state', 'availability_topic': 'bonsaitemp/status', 'unique_id': 'ESPsensoroutdoor_bonsai_humidity', 'device': {'identifiers': 'ecfabc212c26', 'name': 'bonsaitemp', 'sw_version': 'esphome v2021.11.4 Nov 30 2021, 13:59:55', 'model': 'nodemcuv2', 'manufacturer': 'espressif'}, 'platform': 'mqtt'}
2021-12-03 09:36:56 INFO (MainThread) [homeassistant.components.mqtt.discovery] Found new component: sensor bonsaitemp outdoor_bonsai_humidity
2021-12-03 09:36:57 DEBUG (MainThread) [homeassistant.components.mqtt] Subscribing to tasmota/discovery/#, mid: 3
2021-12-03 09:36:58 ERROR (MainThread) [homeassistant.components.weather] Platform met does not generate unique IDs. ID home already exists - ignoring weather.met_no
2021-12-03 09:36:58 ERROR (MainThread) [homeassistant.components.weather] Platform met does not generate unique IDs. ID home already exists - ignoring weather.met_no
2021-12-03 09:36:58 ERROR (MainThread) [homeassistant.components.weather] Platform met does not generate unique IDs. ID home already exists - ignoring weather.met_no
2021-12-03 09:36:58 ERROR (MainThread) [homeassistant.components.weather] Platform met does not generate unique IDs. ID home already exists - ignoring weather.met_no
2021-12-03 09:36:58 ERROR (MainThread) [homeassistant.components.weather] Platform met does not generate unique IDs. ID home already exists - ignoring weather.met_no
2021-12-03 09:36:58 ERROR (MainThread) [homeassistant.components.weather] Platform met does not generate unique IDs. ID home already exists - ignoring weather.met_no
2021-12-03 09:36:58 DEBUG (MainThread) [homeassistant.components.mqtt.discovery] Pending discovery for ('sensor', 'bonsaitemp living_room_temperature'): deque([])
2021-12-03 09:36:58 DEBUG (MainThread) [homeassistant.components.mqtt.discovery] Pending discovery for ('sensor', 'bonsaitemp living_room_humidity'): deque([])
2021-12-03 09:36:58 DEBUG (MainThread) [homeassistant.components.mqtt.discovery] Pending discovery for ('sensor', 'bonsaitemp outdoor_bonsai_temperature'): deque([])
2021-12-03 09:36:58 DEBUG (MainThread) [homeassistant.components.mqtt] Subscribing to bonsaitemp/status, mid: 4
2021-12-03 09:36:58 DEBUG (MainThread) [homeassistant.components.mqtt] Received message on bonsaitemp/status (retained): b'online'
2021-12-03 09:36:58 DEBUG (MainThread) [homeassistant.components.mqtt.discovery] Pending discovery for ('sensor', 'bonsaitemp outdoor_bonsai_humidity'): deque([])
2021-12-03 09:36:58 DEBUG (MainThread) [homeassistant.components.mqtt] Subscribing to bonsaitemp/status, mid: 5
2021-12-03 09:36:58 DEBUG (MainThread) [homeassistant.components.mqtt] Received message on bonsaitemp/status (retained): b'online'
2021-12-03 09:36:58 DEBUG (MainThread) [homeassistant.components.mqtt] Subscribing to bonsaitemp/status, mid: 6
2021-12-03 09:36:58 DEBUG (MainThread) [homeassistant.components.mqtt] Received message on bonsaitemp/status (retained): b'online'
2021-12-03 09:36:58 DEBUG (MainThread) [homeassistant.components.mqtt] Subscribing to bonsaitemp/status, mid: 7
2021-12-03 09:36:58 DEBUG (MainThread) [homeassistant.components.mqtt] Subscribing to bonsaitemp/sensor/living_room_temperature/state, mid: 8
2021-12-03 09:36:58 DEBUG (MainThread) [homeassistant.components.mqtt] Received message on bonsaitemp/status (retained): b'online'
2021-12-03 09:36:58 DEBUG (MainThread) [homeassistant.components.mqtt] Subscribing to bonsaitemp/sensor/living_room_humidity/state, mid: 9
2021-12-03 09:36:58 DEBUG (MainThread) [homeassistant.components.mqtt] Received message on bonsaitemp/sensor/living_room_temperature/state (retained): b'-10.7'
2021-12-03 09:36:58 DEBUG (MainThread) [homeassistant.components.mqtt] Subscribing to bonsaitemp/sensor/outdoor_bonsai_temperature/state, mid: 10
2021-12-03 09:36:58 DEBUG (MainThread) [homeassistant.components.mqtt] Received message on bonsaitemp/sensor/living_room_humidity/state (retained): b'6'
2021-12-03 09:36:58 DEBUG (MainThread) [homeassistant.components.mqtt] Subscribing to bonsaitemp/sensor/outdoor_bonsai_humidity/state, mid: 11
2021-12-03 09:36:58 DEBUG (MainThread) [homeassistant.components.mqtt] Received message on bonsaitemp/sensor/outdoor_bonsai_temperature/state (retained): b'-7.9'
2021-12-03 09:36:58 DEBUG (MainThread) [homeassistant.components.mqtt] Received message on bonsaitemp/sensor/outdoor_bonsai_humidity/state (retained): b'76'
2021-12-03 09:36:58 WARNING (SyncWorker_0) [homeassistant.components.sonos] Failed to connect to configured player '192.168.86.42': HTTPConnectionPool(host='192.168.86.42', port=1400): Max retries exceeded with url: /xml/ZoneGroupTopology1.xml (Caused by NewConnectionError('<urllib3.connection.HTTPConnection object at 0x7efc8a9c80a0>: Failed to establish a new connection: [Errno 111] Connection refused'))
2021-12-03 09:37:05 ERROR (MainThread) [homeassistant.components.google_assistant.smart_home] Error serializing scene.day_3
Traceback (most recent call last):
  File "/usr/src/homeassistant/homeassistant/components/google_assistant/helpers.py", line 511, in sync_serialize
    "baseUrl": get_url(self.hass, prefer_external=True),
  File "/usr/src/homeassistant/homeassistant/helpers/network.py", line 83, in get_url
    request_host = _get_request_host()
  File "/usr/src/homeassistant/homeassistant/helpers/network.py", line 122, in _get_request_host
    raise NoURLAvailableError
homeassistant.helpers.network.NoURLAvailableError
2021-12-03 09:37:05 ERROR (MainThread) [homeassistant.components.google_assistant.smart_home] Error serializing scene.night
Traceback (most recent call last):
  File "/usr/src/homeassistant/homeassistant/components/google_assistant/helpers.py", line 511, in sync_serialize
    "baseUrl": get_url(self.hass, prefer_external=True),
  File "/usr/src/homeassistant/homeassistant/helpers/network.py", line 83, in get_url
    request_host = _get_request_host()
  File "/usr/src/homeassistant/homeassistant/helpers/network.py", line 122, in _get_request_host
    raise NoURLAvailableError
homeassistant.helpers.network.NoURLAvailableError
2021-12-03 09:37:05 ERROR (MainThread) [homeassistant.components.google_assistant.smart_home] Error serializing scene.evening_2
Traceback (most recent call last):
  File "/usr/src/homeassistant/homeassistant/components/google_assistant/helpers.py", line 511, in sync_serialize
    "baseUrl": get_url(self.hass, prefer_external=True),
  File "/usr/src/homeassistant/homeassistant/helpers/network.py", line 83, in get_url
    request_host = _get_request_host()
  File "/usr/src/homeassistant/homeassistant/helpers/network.py", line 122, in _get_request_host
    raise NoURLAvailableError
homeassistant.helpers.network.NoURLAvailableError
2021-12-03 09:37:05 ERROR (MainThread) [homeassistant.components.google_assistant.smart_home] Error serializing scene.away_2
Traceback (most recent call last):
  File "/usr/src/homeassistant/homeassistant/components/google_assistant/helpers.py", line 511, in sync_serialize
    "baseUrl": get_url(self.hass, prefer_external=True),
  File "/usr/src/homeassistant/homeassistant/helpers/network.py", line 83, in get_url
    request_host = _get_request_host()
  File "/usr/src/homeassistant/homeassistant/helpers/network.py", line 122, in _get_request_host
    raise NoURLAvailableError
homeassistant.helpers.network.NoURLAvailableError
2021-12-03 09:37:05 ERROR (MainThread) [homeassistant.components.google_assistant.smart_home] Error serializing scene.nightlight_long_hall
Traceback (most recent call last):
  File "/usr/src/homeassistant/homeassistant/components/google_assistant/helpers.py", line 511, in sync_serialize
    "baseUrl": get_url(self.hass, prefer_external=True),
  File "/usr/src/homeassistant/homeassistant/helpers/network.py", line 83, in get_url
    request_host = _get_request_host()
  File "/usr/src/homeassistant/homeassistant/helpers/network.py", line 122, in _get_request_host
    raise NoURLAvailableError
homeassistant.helpers.network.NoURLAvailableError
2021-12-03 09:37:05 ERROR (MainThread) [homeassistant.components.google_assistant.smart_home] Error serializing scene.test_scene_1
Traceback (most recent call last):
  File "/usr/src/homeassistant/homeassistant/components/google_assistant/helpers.py", line 511, in sync_serialize
    "baseUrl": get_url(self.hass, prefer_external=True),
  File "/usr/src/homeassistant/homeassistant/helpers/network.py", line 83, in get_url
    request_host = _get_request_host()
  File "/usr/src/homeassistant/homeassistant/helpers/network.py", line 122, in _get_request_host
    raise NoURLAvailableError
homeassistant.helpers.network.NoURLAvailableError
2021-12-03 09:37:05 ERROR (MainThread) [homeassistant.components.google_assistant.smart_home] Error serializing scene.test_scene_2
Traceback (most recent call last):
  File "/usr/src/homeassistant/homeassistant/components/google_assistant/helpers.py", line 511, in sync_serialize
    "baseUrl": get_url(self.hass, prefer_external=True),
  File "/usr/src/homeassistant/homeassistant/helpers/network.py", line 83, in get_url
    request_host = _get_request_host()
  File "/usr/src/homeassistant/homeassistant/helpers/network.py", line 122, in _get_request_host
    raise NoURLAvailableError
homeassistant.helpers.network.NoURLAvailableError
2021-12-03 09:37:05 ERROR (MainThread) [homeassistant.components.google_assistant.smart_home] Error serializing scene.test_scene_3
Traceback (most recent call last):
  File "/usr/src/homeassistant/homeassistant/components/google_assistant/helpers.py", line 511, in sync_serialize
    "baseUrl": get_url(self.hass, prefer_external=True),
  File "/usr/src/homeassistant/homeassistant/helpers/network.py", line 83, in get_url
    request_host = _get_request_host()
  File "/usr/src/homeassistant/homeassistant/helpers/network.py", line 122, in _get_request_host
    raise NoURLAvailableError
homeassistant.helpers.network.NoURLAvailableError
2021-12-03 09:37:05 ERROR (MainThread) [homeassistant.components.google_assistant.smart_home] Error serializing scene.test_scene_4
Traceback (most recent call last):
  File "/usr/src/homeassistant/homeassistant/components/google_assistant/helpers.py", line 511, in sync_serialize
    "baseUrl": get_url(self.hass, prefer_external=True),
  File "/usr/src/homeassistant/homeassistant/helpers/network.py", line 83, in get_url
    request_host = _get_request_host()
  File "/usr/src/homeassistant/homeassistant/helpers/network.py", line 122, in _get_request_host
    raise NoURLAvailableError
homeassistant.helpers.network.NoURLAvailableError
2021-12-03 09:37:05 ERROR (MainThread) [homeassistant.components.google_assistant.smart_home] Error serializing light.3_way_lamp
Traceback (most recent call last):
  File "/usr/src/homeassistant/homeassistant/components/google_assistant/helpers.py", line 511, in sync_serialize
    "baseUrl": get_url(self.hass, prefer_external=True),
  File "/usr/src/homeassistant/homeassistant/helpers/network.py", line 83, in get_url
    request_host = _get_request_host()
  File "/usr/src/homeassistant/homeassistant/helpers/network.py", line 122, in _get_request_host
    raise NoURLAvailableError
homeassistant.helpers.network.NoURLAvailableError
2021-12-03 09:37:05 ERROR (MainThread) [homeassistant.components.google_assistant.smart_home] Error serializing script.long_hall_lights_of_when_no_brightnesschange
Traceback (most recent call last):
  File "/usr/src/homeassistant/homeassistant/components/google_assistant/helpers.py", line 511, in sync_serialize
    "baseUrl": get_url(self.hass, prefer_external=True),
  File "/usr/src/homeassistant/homeassistant/helpers/network.py", line 83, in get_url
    request_host = _get_request_host()
  File "/usr/src/homeassistant/homeassistant/helpers/network.py", line 122, in _get_request_host
    raise NoURLAvailableError
homeassistant.helpers.network.NoURLAvailableError
2021-12-03 09:37:05 ERROR (MainThread) [homeassistant.components.google_assistant.smart_home] Error serializing media_player.stua
Traceback (most recent call last):
  File "/usr/src/homeassistant/homeassistant/components/google_assistant/helpers.py", line 511, in sync_serialize
    "baseUrl": get_url(self.hass, prefer_external=True),
  File "/usr/src/homeassistant/homeassistant/helpers/network.py", line 83, in get_url
    request_host = _get_request_host()
  File "/usr/src/homeassistant/homeassistant/helpers/network.py", line 122, in _get_request_host
    raise NoURLAvailableError
homeassistant.helpers.network.NoURLAvailableError
2021-12-03 09:37:05 ERROR (MainThread) [homeassistant.components.google_assistant.smart_home] Error serializing binary_sensor.living_room_door
Traceback (most recent call last):
  File "/usr/src/homeassistant/homeassistant/components/google_assistant/helpers.py", line 511, in sync_serialize
    "baseUrl": get_url(self.hass, prefer_external=True),
  File "/usr/src/homeassistant/homeassistant/helpers/network.py", line 83, in get_url
    request_host = _get_request_host()
  File "/usr/src/homeassistant/homeassistant/helpers/network.py", line 122, in _get_request_host
    raise NoURLAvailableError
homeassistant.helpers.network.NoURLAvailableError
2021-12-03 09:37:05 ERROR (MainThread) [homeassistant.components.google_assistant.smart_home] Error serializing binary_sensor.front_door
Traceback (most recent call last):
  File "/usr/src/homeassistant/homeassistant/components/google_assistant/helpers.py", line 511, in sync_serialize
    "baseUrl": get_url(self.hass, prefer_external=True),
  File "/usr/src/homeassistant/homeassistant/helpers/network.py", line 83, in get_url
    request_host = _get_request_host()
  File "/usr/src/homeassistant/homeassistant/helpers/network.py", line 122, in _get_request_host
    raise NoURLAvailableError
homeassistant.helpers.network.NoURLAvailableError
2021-12-03 09:37:05 ERROR (MainThread) [homeassistant.components.google_assistant.smart_home] Error serializing binary_sensor.cooler_room_door
Traceback (most recent call last):
  File "/usr/src/homeassistant/homeassistant/components/google_assistant/helpers.py", line 511, in sync_serialize
    "baseUrl": get_url(self.hass, prefer_external=True),
  File "/usr/src/homeassistant/homeassistant/helpers/network.py", line 83, in get_url
    request_host = _get_request_host()
  File "/usr/src/homeassistant/homeassistant/helpers/network.py", line 122, in _get_request_host
    raise NoURLAvailableError
homeassistant.helpers.network.NoURLAvailableError
2021-12-03 09:37:05 ERROR (MainThread) [homeassistant.components.google_assistant.smart_home] Error serializing climate.thermostat_guest_toilet
Traceback (most recent call last):
  File "/usr/src/homeassistant/homeassistant/components/google_assistant/helpers.py", line 511, in sync_serialize
    "baseUrl": get_url(self.hass, prefer_external=True),
  File "/usr/src/homeassistant/homeassistant/helpers/network.py", line 83, in get_url
    request_host = _get_request_host()
  File "/usr/src/homeassistant/homeassistant/helpers/network.py", line 122, in _get_request_host
    raise NoURLAvailableError
homeassistant.helpers.network.NoURLAvailableError
2021-12-03 09:37:05 ERROR (MainThread) [homeassistant.components.google_assistant.smart_home] Error serializing climate.thermostat_master_bath
Traceback (most recent call last):
  File "/usr/src/homeassistant/homeassistant/components/google_assistant/helpers.py", line 511, in sync_serialize
    "baseUrl": get_url(self.hass, prefer_external=True),
  File "/usr/src/homeassistant/homeassistant/helpers/network.py", line 83, in get_url
    request_host = _get_request_host()
  File "/usr/src/homeassistant/homeassistant/helpers/network.py", line 122, in _get_request_host
    raise NoURLAvailableError
homeassistant.helpers.network.NoURLAvailableError
2021-12-03 09:37:05 ERROR (MainThread) [homeassistant.components.google_assistant.smart_home] Error serializing climate.thermostat_entrance
Traceback (most recent call last):
  File "/usr/src/homeassistant/homeassistant/components/google_assistant/helpers.py", line 511, in sync_serialize
    "baseUrl": get_url(self.hass, prefer_external=True),
  File "/usr/src/homeassistant/homeassistant/helpers/network.py", line 83, in get_url
    request_host = _get_request_host()
  File "/usr/src/homeassistant/homeassistant/helpers/network.py", line 122, in _get_request_host
    raise NoURLAvailableError
homeassistant.helpers.network.NoURLAvailableError
2021-12-03 09:37:05 ERROR (MainThread) [homeassistant.components.google_assistant.smart_home] Error serializing climate.thermostat_downstairs_toilet
Traceback (most recent call last):
  File "/usr/src/homeassistant/homeassistant/components/google_assistant/helpers.py", line 511, in sync_serialize
    "baseUrl": get_url(self.hass, prefer_external=True),
  File "/usr/src/homeassistant/homeassistant/helpers/network.py", line 83, in get_url
    request_host = _get_request_host()
  File "/usr/src/homeassistant/homeassistant/helpers/network.py", line 122, in _get_request_host
    raise NoURLAvailableError
homeassistant.helpers.network.NoURLAvailableError
2021-12-03 09:37:06 ERROR (MainThread) [homeassistant.components.google_assistant.smart_home] Error serializing climate.thermostat_downstairs_bath
Traceback (most recent call last):
  File "/usr/src/homeassistant/homeassistant/components/google_assistant/helpers.py", line 511, in sync_serialize
    "baseUrl": get_url(self.hass, prefer_external=True),
  File "/usr/src/homeassistant/homeassistant/helpers/network.py", line 83, in get_url
    request_host = _get_request_host()
  File "/usr/src/homeassistant/homeassistant/helpers/network.py", line 122, in _get_request_host
    raise NoURLAvailableError
homeassistant.helpers.network.NoURLAvailableError
2021-12-03 09:37:06 DEBUG (MainThread) [homeassistant.components.mqtt] Transmitting message on homeassistant/status: 'online', mid: 12
2021-12-03 09:37:08 WARNING (MainThread) [homeassistant.components.sonos.entity] Kjøkken cannot reach 172.20.0.4:1400, falling back to polling, functionality may be limited
2021-12-03 09:37:09 ERROR (MainThread) [homeassistant.util.logging] Exception in async_poll when dispatching 'sonos_poll_update-RINCON_5CAAFDE50C3C01400': (datetime.datetime(2021, 12, 3, 9, 37, 8, 870756, tzinfo=datetime.timezone.utc),)
Traceback (most recent call last):
  File "/usr/src/homeassistant/homeassistant/components/sonos/entity.py", line 84, in async_poll
    await self._async_poll()
  File "/usr/src/homeassistant/homeassistant/components/sonos/media_player.py", line 300, in _async_poll
    await self.hass.async_add_executor_job(self._update)
  File "/usr/local/lib/python3.9/concurrent/futures/thread.py", line 52, in run
    result = self.fn(*self.args, **self.kwargs)
  File "/usr/src/homeassistant/homeassistant/components/sonos/media_player.py", line 307, in _update
    self.speaker.update_media()
  File "/usr/src/homeassistant/homeassistant/components/sonos/speaker.py", line 1049, in update_media
    self.update_media_radio(variables)
  File "/usr/src/homeassistant/homeassistant/components/sonos/speaker.py", line 1074, in update_media_radio
    if current_track_metadata := variables.get("current_track_meta_data"):
AttributeError: 'NoneType' object has no attribute 'get'

2021-12-03 09:37:19 ERROR (MainThread) [homeassistant.util.logging] Exception in async_poll when dispatching 'sonos_poll_update-RINCON_5CAAFDE50C3C01400': (datetime.datetime(2021, 12, 3, 9, 37, 18, 871992, tzinfo=datetime.timezone.utc),)
Traceback (most recent call last):
  File "/usr/src/homeassistant/homeassistant/components/sonos/entity.py", line 84, in async_poll
    await self._async_poll()
  File "/usr/src/homeassistant/homeassistant/components/sonos/media_player.py", line 300, in _async_poll
    await self.hass.async_add_executor_job(self._update)
  File "/usr/local/lib/python3.9/concurrent/futures/thread.py", line 52, in run
    result = self.fn(*self.args, **self.kwargs)
  File "/usr/src/homeassistant/homeassistant/components/sonos/media_player.py", line 307, in _update
    self.speaker.update_media()
  File "/usr/src/homeassistant/homeassistant/components/sonos/speaker.py", line 1049, in update_media
    self.update_media_radio(variables)
  File "/usr/src/homeassistant/homeassistant/components/sonos/speaker.py", line 1074, in update_media_radio
    if current_track_metadata := variables.get("current_track_meta_data"):
AttributeError: 'NoneType' object has no attribute 'get'

2021-12-03 09:37:19 DEBUG (MainThread) [homeassistant.components.mqtt] Received message on bonsaitemp/sensor/outdoor_bonsai_temperature/state: b'-7.9'
2021-12-03 09:37:19 DEBUG (MainThread) [homeassistant.components.mqtt] Received message on bonsaitemp/sensor/outdoor_bonsai_humidity/state: b'76'
2021-12-03 09:37:29 ERROR (MainThread) [homeassistant.util.logging] Exception in async_poll when dispatching 'sonos_poll_update-RINCON_5CAAFDE50C3C01400': (datetime.datetime(2021, 12, 3, 9, 37, 28, 878871, tzinfo=datetime.timezone.utc),)
Traceback (most recent call last):
  File "/usr/src/homeassistant/homeassistant/components/sonos/entity.py", line 84, in async_poll
    await self._async_poll()
  File "/usr/src/homeassistant/homeassistant/components/sonos/media_player.py", line 300, in _async_poll
    await self.hass.async_add_executor_job(self._update)
  File "/usr/local/lib/python3.9/concurrent/futures/thread.py", line 52, in run
    result = self.fn(*self.args, **self.kwargs)
  File "/usr/src/homeassistant/homeassistant/components/sonos/media_player.py", line 307, in _update
    self.speaker.update_media()
  File "/usr/src/homeassistant/homeassistant/components/sonos/speaker.py", line 1049, in update_media
    self.update_media_radio(variables)
  File "/usr/src/homeassistant/homeassistant/components/sonos/speaker.py", line 1074, in update_media_radio
    if current_track_metadata := variables.get("current_track_meta_data"):
AttributeError: 'NoneType' object has no attribute 'get'

2021-12-03 09:37:39 ERROR (MainThread) [homeassistant.util.logging] Exception in async_poll when dispatching 'sonos_poll_update-RINCON_5CAAFDE50C3C01400': (datetime.datetime(2021, 12, 3, 9, 37, 38, 879352, tzinfo=datetime.timezone.utc),)
Traceback (most recent call last):
  File "/usr/src/homeassistant/homeassistant/components/sonos/entity.py", line 84, in async_poll
    await self._async_poll()
  File "/usr/src/homeassistant/homeassistant/components/sonos/media_player.py", line 300, in _async_poll
    await self.hass.async_add_executor_job(self._update)
  File "/usr/local/lib/python3.9/concurrent/futures/thread.py", line 52, in run
    result = self.fn(*self.args, **self.kwargs)
  File "/usr/src/homeassistant/homeassistant/components/sonos/media_player.py", line 307, in _update
    self.speaker.update_media()
  File "/usr/src/homeassistant/homeassistant/components/sonos/speaker.py", line 1049, in update_media
    self.update_media_radio(variables)
  File "/usr/src/homeassistant/homeassistant/components/sonos/speaker.py", line 1074, in update_media_radio
    if current_track_metadata := variables.get("current_track_meta_data"):
AttributeError: 'NoneType' object has no attribute 'get'

2021-12-03 09:37:49 ERROR (MainThread) [homeassistant.util.logging] Exception in async_poll when dispatching 'sonos_poll_update-RINCON_5CAAFDE50C3C01400': (datetime.datetime(2021, 12, 3, 9, 37, 48, 880353, tzinfo=datetime.timezone.utc),)
Traceback (most recent call last):
  File "/usr/src/homeassistant/homeassistant/components/sonos/entity.py", line 84, in async_poll
    await self._async_poll()
  File "/usr/src/homeassistant/homeassistant/components/sonos/media_player.py", line 300, in _async_poll
    await self.hass.async_add_executor_job(self._update)
  File "/usr/local/lib/python3.9/concurrent/futures/thread.py", line 52, in run
    result = self.fn(*self.args, **self.kwargs)
  File "/usr/src/homeassistant/homeassistant/components/sonos/media_player.py", line 307, in _update
    self.speaker.update_media()
  File "/usr/src/homeassistant/homeassistant/components/sonos/speaker.py", line 1049, in update_media
    self.update_media_radio(variables)
  File "/usr/src/homeassistant/homeassistant/components/sonos/speaker.py", line 1074, in update_media_radio
    if current_track_metadata := variables.get("current_track_meta_data"):
AttributeError: 'NoneType' object has no attribute 'get'

2021-12-03 09:37:49 DEBUG (MainThread) [homeassistant.components.mqtt] Received message on bonsaitemp/sensor/outdoor_bonsai_temperature/state: b'-8.0'
2021-12-03 09:37:49 DEBUG (MainThread) [homeassistant.components.mqtt] Received message on bonsaitemp/sensor/outdoor_bonsai_humidity/state: b'76'
2021-12-03 09:37:58 WARNING (SyncWorker_1) [homeassistant.components.sonos] Failed to connect to configured player '192.168.86.42': HTTPConnectionPool(host='192.168.86.42', port=1400): Max retries exceeded with url: /xml/ZoneGroupTopology1.xml (Caused by NewConnectionError('<urllib3.connection.HTTPConnection object at 0x7efc906081f0>: Failed to establish a new connection: [Errno 111] Connection refused'))
2021-12-03 09:37:59 ERROR (MainThread) [homeassistant.util.logging] Exception in async_poll when dispatching 'sonos_poll_update-RINCON_5CAAFDE50C3C01400': (datetime.datetime(2021, 12, 3, 9, 37, 58, 882215, tzinfo=datetime.timezone.utc),)
Traceback (most recent call last):
  File "/usr/src/homeassistant/homeassistant/components/sonos/entity.py", line 84, in async_poll
    await self._async_poll()
  File "/usr/src/homeassistant/homeassistant/components/sonos/media_player.py", line 300, in _async_poll
    await self.hass.async_add_executor_job(self._update)
  File "/usr/local/lib/python3.9/concurrent/futures/thread.py", line 52, in run
    result = self.fn(*self.args, **self.kwargs)
  File "/usr/src/homeassistant/homeassistant/components/sonos/media_player.py", line 307, in _update
    self.speaker.update_media()
  File "/usr/src/homeassistant/homeassistant/components/sonos/speaker.py", line 1049, in update_media
    self.update_media_radio(variables)
  File "/usr/src/homeassistant/homeassistant/components/sonos/speaker.py", line 1074, in update_media_radio
    if current_track_metadata := variables.get("current_track_meta_data"):
AttributeError: 'NoneType' object has no attribute 'get'

2021-12-03 09:38:09 ERROR (MainThread) [homeassistant.util.logging] Exception in async_poll when dispatching 'sonos_poll_update-RINCON_5CAAFDE50C3C01400': (datetime.datetime(2021, 12, 3, 9, 38, 8, 885176, tzinfo=datetime.timezone.utc),)
Traceback (most recent call last):
  File "/usr/src/homeassistant/homeassistant/components/sonos/entity.py", line 84, in async_poll
    await self._async_poll()
  File "/usr/src/homeassistant/homeassistant/components/sonos/media_player.py", line 300, in _async_poll
    await self.hass.async_add_executor_job(self._update)
  File "/usr/local/lib/python3.9/concurrent/futures/thread.py", line 52, in run
    result = self.fn(*self.args, **self.kwargs)
  File "/usr/src/homeassistant/homeassistant/components/sonos/media_player.py", line 307, in _update
    self.speaker.update_media()
  File "/usr/src/homeassistant/homeassistant/components/sonos/speaker.py", line 1049, in update_media
    self.update_media_radio(variables)
  File "/usr/src/homeassistant/homeassistant/components/sonos/speaker.py", line 1074, in update_media_radio
    if current_track_metadata := variables.get("current_track_meta_data"):
AttributeError: 'NoneType' object has no attribute 'get'

2021-12-03 09:38:19 ERROR (MainThread) [homeassistant.util.logging] Exception in async_poll when dispatching 'sonos_poll_update-RINCON_5CAAFDE50C3C01400': (datetime.datetime(2021, 12, 3, 9, 38, 18, 886035, tzinfo=datetime.timezone.utc),)
Traceback (most recent call last):
  File "/usr/src/homeassistant/homeassistant/components/sonos/entity.py", line 84, in async_poll
    await self._async_poll()
  File "/usr/src/homeassistant/homeassistant/components/sonos/media_player.py", line 300, in _async_poll
    await self.hass.async_add_executor_job(self._update)
  File "/usr/local/lib/python3.9/concurrent/futures/thread.py", line 52, in run
    result = self.fn(*self.args, **self.kwargs)
  File "/usr/src/homeassistant/homeassistant/components/sonos/media_player.py", line 307, in _update
    self.speaker.update_media()
  File "/usr/src/homeassistant/homeassistant/components/sonos/speaker.py", line 1049, in update_media
    self.update_media_radio(variables)
  File "/usr/src/homeassistant/homeassistant/components/sonos/speaker.py", line 1074, in update_media_radio
    if current_track_metadata := variables.get("current_track_meta_data"):
AttributeError: 'NoneType' object has no attribute 'get'

2021-12-03 09:38:19 DEBUG (MainThread) [homeassistant.components.mqtt] Received message on bonsaitemp/sensor/outdoor_bonsai_temperature/state: b'-8.0'
2021-12-03 09:38:19 DEBUG (MainThread) [homeassistant.components.mqtt] Received message on bonsaitemp/sensor/outdoor_bonsai_humidity/state: b'76'
2021-12-03 09:38:29 ERROR (MainThread) [homeassistant.util.logging] Exception in async_poll when dispatching 'sonos_poll_update-RINCON_5CAAFDE50C3C01400': (datetime.datetime(2021, 12, 3, 9, 38, 28, 892067, tzinfo=datetime.timezone.utc),)
Traceback (most recent call last):
  File "/usr/src/homeassistant/homeassistant/components/sonos/entity.py", line 84, in async_poll
    await self._async_poll()
  File "/usr/src/homeassistant/homeassistant/components/sonos/media_player.py", line 300, in _async_poll
    await self.hass.async_add_executor_job(self._update)
  File "/usr/local/lib/python3.9/concurrent/futures/thread.py", line 52, in run
    result = self.fn(*self.args, **self.kwargs)
  File "/usr/src/homeassistant/homeassistant/components/sonos/media_player.py", line 307, in _update
    self.speaker.update_media()
  File "/usr/src/homeassistant/homeassistant/components/sonos/speaker.py", line 1049, in update_media
    self.update_media_radio(variables)
  File "/usr/src/homeassistant/homeassistant/components/sonos/speaker.py", line 1074, in update_media_radio
    if current_track_metadata := variables.get("current_track_meta_data"):
AttributeError: 'NoneType' object has no attribute 'get'

2021-12-03 09:38:39 ERROR (MainThread) [homeassistant.util.logging] Exception in async_poll when dispatching 'sonos_poll_update-RINCON_5CAAFDE50C3C01400': (datetime.datetime(2021, 12, 3, 9, 38, 38, 892414, tzinfo=datetime.timezone.utc),)
Traceback (most recent call last):
  File "/usr/src/homeassistant/homeassistant/components/sonos/entity.py", line 84, in async_poll
    await self._async_poll()
  File "/usr/src/homeassistant/homeassistant/components/sonos/media_player.py", line 300, in _async_poll
    await self.hass.async_add_executor_job(self._update)
  File "/usr/local/lib/python3.9/concurrent/futures/thread.py", line 52, in run
    result = self.fn(*self.args, **self.kwargs)
  File "/usr/src/homeassistant/homeassistant/components/sonos/media_player.py", line 307, in _update
    self.speaker.update_media()
  File "/usr/src/homeassistant/homeassistant/components/sonos/speaker.py", line 1049, in update_media
    self.update_media_radio(variables)
  File "/usr/src/homeassistant/homeassistant/components/sonos/speaker.py", line 1074, in update_media_radio
    if current_track_metadata := variables.get("current_track_meta_data"):
AttributeError: 'NoneType' object has no attribute 'get'

